<?xml version="1.0"?>
<robot xmlns:xacro="http://www.ros.org/wiki/xacro" name="wheel_parameters">
    
    <xacro:property name="wheel_const"   value="0.0833333333"/>
    <xacro:property name="wheel_const2"  value="0.5"/>
    <xacro:property name="wheel_mass"    value="0.25"/>
    <xacro:property name="wheel_radius"  value="0.15"/>
    <xacro:property name="wheel_height"  value="0.1"/>

    <xacro:macro name="wheel" params="name x y z">
        <link name="${name}_wheel_link">
            <inertial>
                <origin xyz="0.0 0.0 0.0" rpy="0.0 0.0 0.0"/>
                <mass value="${wheel_mass}"/>
                <inertia ixx="${(wheel_const * wheel_mass) * ( 3 * (wheel_radius * wheel_radius) + (wheel_height * wheel_height))}" ixy="0.0" ixz="0.0" 
                                   iyy="${(wheel_const * wheel_mass) * ( 3 * (wheel_radius * wheel_radius) + (wheel_height * wheel_height))}" iyz="0.0" 
                                                                                     izz="${wheel_const2 * wheel_mass * (wheel_radius * wheel_radius)}"/>
            </inertial>
            <visual name="">
                <origin xyz="0.0 0.0 0.0" rpy="0.0 0.0 0.0"/>
                <geometry>
                    <cylinder radius="${wheel_radius}" length="${wheel_height}"/>
                </geometry>
                <material name="white">
                    <color rgba="1.0 1.0 1.0 1.0"/>
                    <texture filename=""/>
                </material>
            </visual>
            <collision>
                <origin xyz="0.0 0.0 0.0" rpy="0.0 0.0 0.0"/>
                <geometry>
                    <cylinder radius="0.15" length="0.1"/>
                </geometry>
            </collision>
        </link>

        <joint name="${name}_wheel_joint" type="continuous">
            <origin xyz="${x} ${y} ${z}" rpy="1.570796 0.0 0.0"/>
            <parent link="chassis_link"/>
            <child link="${name}_wheel_link"/>
            <axis xyz="0.0 0.0 -1.0"/>
        </joint>

        <transmission name="${name}_wheel_trans">
            <type>transmission_interface/SimpleTransmission</type>
            <actuator name="${name}_wheel_motor">
              <mechanicalReduction>1</mechanicalReduction>
            </actuator>
            <joint name="${name}_wheel_joint">
              <hardwareInterface>hardware_interface/VelocityJointInterface</hardwareInterface>
            </joint>
        </transmission>
    
        <gazebo reference="${name}_wheel_link">
            <mu1 value="1.0"/>
            <mu2 value="2.0"/>
            <kp value="10000000.0" />
            <kd value="1.0" />
            <material>Gazebo/Grey</material>
        </gazebo>
    </xacro:macro>

</robot>